Workbook
Name A: [1]Bilanci!$C$19
Name AC: REPT(CHAR(10),2)
Name CFM: [1]Bilanci!$C$14
Name consumi: [1]Bilanci!$C$10
Name CV: [1]Bilanci!$C$12
Name Data: Relazione!$L$4
Name fpas: EDATE([0]!fp,12)
Name ic: "Inserire nuovo conto"
Name IncConsumi: [1]Bilanci!$D$10
Name IncCV: [1]Bilanci!$D$12
Name IRAP: [1]Bilanci!$C$24
Name IRES: [1]Bilanci!$C$23
Name me: IF(m>0,m,12)
Name n: +MID(CELL("nomefile"),FIND("[",CELL("nomefile")),100)&"!"
Name nBi: +LEFT(CELL("nomefile"),FIND("[",CELL("nomefile"))-1)&"\BplanEasy2.0.pbix"
Name NomeSerie: OFFSET([1]Risultati!$C$55,0,0,[1]Risultati!$R$68)
Name NS: OR([1]Risultati!$B1=0,[1]Risultati!$B1="")
Name Nscen: #REF!
Name OF: [1]Bilanci!$C$21
Name p: +CHAR(149)& " "
Name pu: ". "
Name RAT: OFFSET(STR,0,1)
Name Ricavi: [1]Bilanci!$C$7
Name Risultati: [1]!Tabella2[[#Headers],[Id]]
Name s: " "
Name Serie: OFFSET([1]Risultati!$A$55,0,[1]Risultati!$Q$68,[1]Risultati!$R$68,1)
Name TB: IF(t="Abbreviato Cee",1,IF(t="CEE",2,3))
Name TBA: IF(ta="Abbreviato Cee",1,IF(ta="CEE",2,3))
Name TSI: +VLOOKUP(Tipo&1,[0]!ind,3,0)
Name TSII: +VLOOKUP(Tipo&2,[0]!ind,3,0)
Name v: ", "
Name x: OR(ind="",LEFT(ind,3)="Pdt")

Sheet SEZIONI 1-2
C2: Istruzioni: Spuntare i riquadri appositi di ogni sezione e compilare le colonne azzurre se ritenuto necessario.
A3: Nome Impresa | C3: ALFA S.R.L
A5: Data Verifica | C5: 45253 | D5: Firmata da | E5: XXX
A8: 1 | D8: Il requisito dell’organizzazione dell’impresa | H8: Frase VERO | I8: Frase FALSO | J8: Frase suggerimento per commenti in caso di risposta positiva | K8: Frase suggerimento per commenti in caso di risposta negativa | L8: Frase Completa | M8: Suggerimento
C9: 1.1 | E9: L’impresa dispone delle risorse chiave (umane e tecniche) per la conduzione dell’attività? | F9: FALSE | H9: L’impresa dispone delle risorse chiave (umane e tecniche) per la conduzione dell’attività. | I9: L’impresa non dispone delle risorse chiave (umane e tecniche) per la conduzione dell’attività. | J9: Aggiungere eventuali commenti | K9: L’impresa come pensa di procurarsi tali risorse? | L9: =+OFFSET(F9,0,IF(F9,2,3)) -> L’impresa non dispone delle risorse chiave (umane e tecniche) per la conduzione dell’attività. | M9: =+OFFSET(F9,0,IF(F9,4,5)) -> L’impresa come pensa di procurarsi tali risorse?
C10: 1.2 | E10: L’impresa dispone delle competenze tecniche occorrenti per le iniziative industriali che l’imprenditore intende adottare? | F10: FALSE | H10: Da un punto di vista tecnico/economico, l’impresa dispone delle competenze necessarie per le iniziative industriali che l’imprenditore intende adottare. | I10: Da un punto di vista tecnico/economico, l’impresa non dispone delle competenze necessarie per le iniziative industriali che l’imprenditore intende adottare. | J10: Aggiungere eventuali commenti | K10: Indicare le iniziative industriali per le quali l'impresa sia realisticamente in grado di disporre, eventualmente acquisendole sul mercato, delle competenze tecniche occorrenti: | L10: =+OFFSET(F10,0,IF(F10,2,3)) -> Da un punto di vista tecnico/economico, l’impresa non dispone delle competenze necessarie per le iniziative industriali che l’imprenditore intende adottare. | M10: =+OFFSET(F10,0,IF(F10,4,5)) -> Indicare le iniziative industriali per le quali l'impresa sia realisticamente in grado di disporre, eventualmente acquisendole sul mercato, delle competenze tecniche occorrenti:
C11: 1.3 | E11: L’impresa ha predisposto un monitoraggio continuativo dell’andamento aziendale? | F11: FALSE | H11: Il sistema informativo aziendale prevede un adeguato sistema di monitoraggio continuo dell'andamento aziendale. | I11: Il monitoraggio dell'andamento aziendale appare inadeguato. | J11: Aggiungere eventuali commenti | K11: Indicare cosa intende fare per controllare la gestione | L11: =+OFFSET(F11,0,IF(F11,2,3)) -> Il monitoraggio dell'andamento aziendale appare inadeguato. | M11: =+OFFSET(F11,0,IF(F11,4,5)) -> Indicare cosa intende fare per controllare la gestione
E12: L’impresa ha attivato il confronto con i dati di andamento del precedente esercizio, in termini di ricavi? | F12: FALSE | H12: I ricavi sono costantemente monitorati. | I12: I ricavi non sono controllati in maniera adeguata. | J12: Aggiungere eventuali commenti | K12: Indicare quale controllo viene fatto e come si intende intervenire per migliorare il sistema di controllo. | L12: =+OFFSET(F12,0,IF(F12,2,3)) -> I ricavi non sono controllati in maniera adeguata. | M12: =+OFFSET(F12,0,IF(F12,4,5)) -> Indicare quale controllo viene fatto e come si intende intervenire per migliorare il sistema di controllo.
E13: L’impresa ha quanto meno attivato il confronto con i dati di andamento del precedente esercizio, in termini di portafogli ordini ? | F13: FALSE | H13: Gli ordini sono costantemente monitorati. | I13: Gli ordini non sono controllati in maniera adeguata. | J13: Aggiungere eventuali commenti | K13: Indicare quale controllo viene fatto e come si intende intervenire per migliorare il sistema di controllo. | L13: =+OFFSET(F13,0,IF(F13,2,3)) -> Gli ordini non sono controllati in maniera adeguata. | M13: =+OFFSET(F13,0,IF(F13,4,5)) -> Indicare quale controllo viene fatto e come si intende intervenire per migliorare il sistema di controllo.
E14: L’impresa ha quanto meno attivato il confronto con i dati di andamento del precedente esercizio, in termini di Posizione Finanziaria Netta? | F14: FALSE | H14: La posizione finanziaria netta è costantemente monitorata. | I14: La posizione finanziaria netta non è costantemente monitorata. | J14: Aggiungere eventuali commenti | K14: Indicare quale controllo viene fatto e come si intende intervenire per migliorare il sistema di controllo. | L14: =+OFFSET(F14,0,IF(F14,2,3)) -> La posizione finanziaria netta non è costantemente monitorata. | M14: =+OFFSET(F14,0,IF(F14,4,5)) -> Indicare quale controllo viene fatto e come si intende intervenire per migliorare il sistema di controllo.
C15: 1.4 | E15: L’impresa è in grado di stimare l’andamento gestionale anche ricorrendo ad indicatori chiave gestionali (KPI) che consentano valutazioni rapide in continuo? | F15: FALSE | H15: L'impresa ha altresì introdotto un sistema di KPI che consentono valutazioni rapide e continue, | I15: L'impresa non fa ancora ricorso a KPI che consentono valutazioni rapide e continue, | L15: =+OFFSET(F15,0,IF(F15,2,3)) -> L'impresa non fa ancora ricorso a KPI che consentono valutazioni rapide e continue, | M15: =+OFFSET(F15,0,IF(F15,4,5)) -> 0
E16: L’impresa è in grado di individuare gli indicatori di produttività coerenti con il proprio modello di business ed il proprio settore di attività, e di raccogliere ulteriori informazioni per la valutazione dell’andamento tendenziale? | F16: FALSE | H16: è in grado di individuare gli indicatori di produttività coerenti con il proprio modello di business ed il proprio settore di attività, e di raccogliere ulteriori informazioni per la valutazione dell’andamento tendenziale. | I16: non è in grado di individuare gli indicatori di produttività coerenti con il proprio modello di business ed il proprio settore di attività, e di raccogliere ulteriori informazioni per la valutazione dell’andamento tendenziale. | J16: Descrivere facendo riferimento ai metodi utilizzati (BSC, BMC, KPI, ecc) | K16: Indicare se e quando intende adottare i KPI, quale metodologia intende adottare (BSC, BMC, KPI, ecc) e quali controlli avvengono per misurare la produttività aziendale. | L16: =+OFFSET(F16,0,IF(F16,2,3)) -> non è in grado di individuare gli indicatori di produttività coerenti con il proprio modello di business ed il proprio settore di attività, e di raccogliere ulteriori informazioni per la valutazione dell’andamento tendenziale. | M16: =+OFFSET(F16,0,IF(F16,4,5)) -> Indicare se e quando intende adottare i KPI, quale metodologia intende adottare (BSC, BMC, KPI, ecc) e quali controlli avvengono per misurare la produttività aziendale.
C17: 1.5 | E17: L’impresa dispone di un piano di tesoreria a 12 mesi? | F17: FALSE | H17: L'impresa dispone di un piano di tesoreria a 12 mesi, | I17: L'impresa non dispone di un piano di tesoreria a 12 mesi. | J17: Aggiungere eventuali commenti | K17: Spiegare le motivazioni per le quali non è stato redatto un piano di tesoreria e come si intende rimuovere gli ostacoli. | L17: =+OFFSET(F17,0,IF(F17,2,3)) -> L'impresa non dispone di un piano di tesoreria a 12 mesi. | M17: =+OFFSET(F17,0,IF(F17,4,5)) -> Spiegare le motivazioni per le quali non è stato redatto un piano di tesoreria e come si intende rimuovere gli ostacoli.
E18: L’impresa è in grado di predisporre un prospetto delle stime delle entrate e delle uscite finanziare almeno a 13 settimane, il cui scostamento con l’andamento corrente dovrà essere valutato a consuntivo? | F18: FALSE | H18: È in grado di predisporre un prospetto delle stime delle entrate e delle uscite finanziare almeno a 13 settimane, il cui scostamento con l’andamento corrente dovrà essere valutato a consuntivo. | I18: Non è in grado di predisporre un prospetto delle stime delle entrate e delle uscite finanziare almeno a 13 settimane, il cui scostamento con l’andamento corrente dovrà essere valutato a consuntivo. | J18: Aggiungere eventuali commenti | K18: Spiegare le motivazioni per le quali non è stato redatto il prospetto e come si intende rimuovere gli ostacoli. | L18: =+OFFSET(F18,0,IF(F18,2,3)) -> Non è in grado di predisporre un prospetto delle stime delle entrate e delle uscite finanziare almeno a 13 settimane, il cui scostamento con l’andamento corrente dovrà essere valutato a consuntivo. | M18: =+OFFSET(F18,0,IF(F18,4,5)) -> Spiegare le motivazioni per le quali non è stato redatto il prospetto e come si intende rimuovere gli ostacoli.
L19: =+OFFSET(F19,0,IF(F19,2,3)) -> 0 | M19: =+OFFSET(F19,0,IF(F19,4,5)) -> 0
A20: 2 | D20: Rilevazione della situazione contabile e dell’andamento corrente | H20: Frase VERO | I20: Frase FALSO | J20: Frase suggerimento per commenti in caso di risposta positiva | K20: Frase suggerimento per commenti in caso di risposta negativa | L20: =+OFFSET(F20,0,IF(F20,2,3)) -> Frase FALSO | M20: =+OFFSET(F20,0,IF(F20,4,5)) -> Frase suggerimento per commenti in caso di risposta negativa
C21: 2.1 | E21: L’impresa dispone di una situazione contabile recante le rettifiche di competenza e gli assestamenti di chiusura, nel rispetto del principio contabile OIC 30, quanto più possibile aggiornata e comunque non anteriore di oltre 120 giorni? | F21: FALSE | H21: È stata disposta una situazione contabile recante le rettifiche di competenza e gli assestamenti di chiusura, nel rispetto del principio contabile OIC 30. | I21: L'ultima situazione redatta risale a oltre 120 giorni. | J21: Aggiungere eventuali commenti | K21: Indicare i tempi previsti per una situazione aggiornata | L21: =+OFFSET(F21,0,IF(F21,2,3)) -> L'ultima situazione redatta risale a oltre 120 giorni. | M21: =+OFFSET(F21,0,IF(F21,4,5)) -> Indicare i tempi previsti per una situazione aggiornata
C22: 2.2 | E22: La situazione debitoria è completa ed affidabile? | F22: FALSE | H22: La situazione è da considerarsi affidabile per quanto concerne la corretta rappresentazione della situazione debitoria dell'impresa. | I22: La situazione non è da considerarsi affidabile per quanto concerne la corretta rappresentazione della situazione debitoria dell'impresa. | J22: Aggiungere eventuali commenti | K22: Indicare le cause che impediscono un'affidabilità della situazione debitoria. | L22: =+OFFSET(F22,0,IF(F22,2,3)) -> La situazione non è da considerarsi affidabile per quanto concerne la corretta rappresentazione della situazione debitoria dell'impresa. | M22: =+OFFSET(F22,0,IF(F22,4,5)) -> Indicare le cause che impediscono un'affidabilità della situazione debitoria.
E23: Il valore contabile dei cespiti è adeguato e non è inferiore al maggiore tra il valore recuperabile e quelli di mercato? | F23: FALSE | H23: Non sono presenti minusvalenze latenti o potenziali insite nella valutazione dei cespiti. | I23: Il maggior contabile dei cespiti è superiore al valore di realizzo e a quello di mercato. | J23: Aggiungere eventuali commenti | K23: L'impresa intende quanto meno appostare con prudenza adeguati fondi rischi e fondi per l’adeguamento delle attività e delle passività? | L23: =+OFFSET(F23,0,IF(F23,2,3)) -> Il maggior contabile dei cespiti è superiore al valore di realizzo e a quello di mercato. | M23: =+OFFSET(F23,0,IF(F23,4,5)) -> L'impresa intende quanto meno appostare con prudenza adeguati fondi rischi e fondi per l’adeguamento delle attività e delle passività?
C24: 2.3 | E24: È disponibile un prospetto recante l’anzianità dei crediti commerciali? | F24: FALSE | H24: La funzione amministrativa dispone di un prospetto recante l’anzianità dei crediti commerciali e | I24: Non esiste in azienda un prospetto recante l’anzianità dei crediti commerciali | L24: =+OFFSET(F24,0,IF(F24,2,3)) -> Non esiste in azienda un prospetto recante l’anzianità dei crediti commerciali | M24: =+OFFSET(F24,0,IF(F24,4,5)) -> 0
E25: Il prospetto comprende le cause del ritardo di incasso tale da consentire una valutazione oggettiva dei rischi di perdite sui crediti e una stima prudente dei tempi di incasso? | F25: FALSE | H25: le cause del ritardo di incasso tale da consentire una valutazione oggettiva dei rischi di perdite sui crediti e una stima prudente dei tempi di incasso. | I25: , non sono state analizzate le cause del ritardo di incasso tale da consentire una valutazione oggettiva dei rischi di perdite sui crediti e una stima prudente dei tempi di incasso. | J25: Aggiungere eventuali commenti | K25: Indicare eventuali interventi in termini di credit management | L25: =+OFFSET(F25,0,IF(F25,2,3)) -> , non sono state analizzate le cause del ritardo di incasso tale da consentire una valutazione oggettiva dei rischi di perdite sui crediti e una stima prudente dei tempi di incasso. | M25: =+OFFSET(F25,0,IF(F25,4,5)) -> Indicare eventuali interventi in termini di credit management
E26: I crediti commerciali sono suddivisibili in relazione alla loro anzianità? | F26: FALSE | H26: I crediti sono suddivisibili in base alla loro anzianità. | I26: Non vi sono informazioni sufficienti per suddividere i crediti in base all'anzianità. | J26: Aggiungere eventuali commenti | K26: Indicare eventuali interventi in termini di credit management | L26: =+OFFSET(F26,0,IF(F26,2,3)) -> Non vi sono informazioni sufficienti per suddividere i crediti in base all'anzianità. | M26: =+OFFSET(F26,0,IF(F26,4,5)) -> Indicare eventuali interventi in termini di credit management
E27: Per gli scaduti che superano la fisiologia (tempi ordinari di pagamento, pur oltre la scadenza contrattuale, che caratterizzano il settore), la stima del momento dell’incasso è particolarmente prudente? | F27: FALSE | H27: Per gli scaduti che superano la fisiologia (tempi ordinari di pagamento, pur oltre la scadenza contrattuale, che caratterizzano il settore), la stima del momento dell’incasso è particolarmente prudente. | I27: Per gli scaduti che superano la fisiologia (tempi ordinari di pagamento, pur oltre la scadenza contrattuale, che caratterizzano il settore), la stima del momento dell’incasso non è da considerarsi sufficientemente prudente. | J27: Aggiungere eventuali commenti | K27: Quali elementi non sono valutati con la dovuta prudenza? | L27: =+OFFSET(F27,0,IF(F27,2,3)) -> Per gli scaduti che superano la fisiologia (tempi ordinari di pagamento, pur oltre la scadenza contrattuale, che caratterizzano il settore), la stima del momento dell’incasso non è da considerarsi sufficientemente prudente. | M27: =+OFFSET(F27,0,IF(F27,4,5)) -> Quali elementi non sono valutati con la dovuta prudenza?
C28: 2.4 | E28: È disponibile un prospetto recante le rimanenze di magazzino con i tempi di movimentazione che consenta di individuare le giacenze oggetto di lenta rotazione? | F28: FALSE | H28: È disponibile un prospetto recante le rimanenze di magazzino con i tempi di movimentazione che consenta di individuare le giacenze oggetto di lenta rotazione. | I28: Non è stato redatto alcun prospetto recante le rimanenze di magazzino con i tempi di movimentazione che consenta di individuare le giacenze oggetto di lenta rotazione. | J28: Quali sono le giacenze di magazzino a lenta rotazione? | K28: Indicare le cause e gli interventi in merito | L28: =+OFFSET(F28,0,IF(F28,2,3)) -> Non è stato redatto alcun prospetto recante le rimanenze di magazzino con i tempi di movimentazione che consenta di individuare le giacenze oggetto di lenta rotazione. | M28: =+OFFSET(F28,0,IF(F28,4,5)) -> Indicare le cause e gli interventi in merito
C29: 2.5 | E29: È disponibile un prospetto di riconciliazione tra la contabilità e quanto risultante dal certificato unico dei debiti tributari,dalla situazione debitoria complessiva dell’Agente della Riscossione? | F29: FALSE | H29: L'impresa dispone di un prospetto di riconciliazione tra la contabilità e quanto risultante dal certificato unico dei debiti tributari, dalla situazione debitoria complessiva dell’Agente della Riscossione. | I29: L'impresa non ha redatto un prospetto di riconciliazione tra la contabilità e quanto risultante dal certificato unico dei debiti tributari, dalla situazione debitoria complessiva dell’Agente della Riscossione. | J29: Indicare le differenze significative | K29: Indicare le cause e gli interventi in merito | L29: =+OFFSET(F29,0,IF(F29,2,3)) -> L'impresa non ha redatto un prospetto di riconciliazione tra la contabilità e quanto risultante dal certificato unico dei debiti tributari, dalla situazione debitoria complessiva dell’Agente della Riscossione. | M29: =+OFFSET(F29,0,IF(F29,4,5)) -> Indicare le cause e gli interventi in merito
E30: È disponibile un prospetto di riconciliazione tra la contabilità e quanto risultante dal certificato per debiti contributivi e assicurativi? | F30: FALSE | H30: Non ha compilato un prospetto di riconciliazione tra la contabilità e quanto risultante dal certificato unico dei debiti contributivi e assicurativi | I30: Ha redatto un prospetto di riconciliazione tra la contabilità e quanto risultante dal certificato unico dei debiti contributivi e assicurativi | J30: Indicare le differenze significative. | K30: Indicare le cause e gli interventi in merito | L30: =+OFFSET(F30,0,IF(F30,2,3)) -> Ha redatto un prospetto di riconciliazione tra la contabilità e quanto risultante dal certificato unico dei debiti contributivi e assicurativi | M30: =+OFFSET(F30,0,IF(F30,4,5)) -> Indicare le cause e gli interventi in merito
E31: Viene esaminata periodicamente la Centrale Rischi di Banca d'Italia? | F31: FALSE | H31: La Centrale rischi di Banca D'Italia viene esaminata periodicamente e | I31: La Centrale rischi di Banca D'Italia non viene esaminata periodicamente e | L31: =+OFFSET(F31,0,IF(F31,2,3)) -> La Centrale rischi di Banca D'Italia non viene esaminata periodicamente e | M31: =+OFFSET(F31,0,IF(F31,4,5)) -> 0
E32: È disponibile un prospetto di riconciliazione tra la contabilità e quanto risultante dalla Centrale Rischi? | F32: FALSE | H32: riconciliata con la contabilità. | I32: non riconciliata con la contabilità. | J32: Aggiungere eventuali commenti | K32: Indicare le cause e gli interventi in merito | L32: =+OFFSET(F32,0,IF(F32,2,3)) -> non riconciliata con la contabilità. | M32: =+OFFSET(F32,0,IF(F32,4,5)) -> Indicare le cause e gli interventi in merito
C33: 2.6 | E33: Si è tenuto adeguatamente conto dei rischi di passività potenziali? | F33: FALSE | H33: Il sistema di controllo dei rischi tiene conto anche delle passività potenziali. | I33: L’azienda non ha tenuto conto delle passività potenziali. | J33: Di che entità sono eventuali passività potenziali? | K33: Di che entità sono eventuali passività potenziali? | L33: =+OFFSET(F33,0,IF(F33,2,3)) -> L’azienda non ha tenuto conto delle passività potenziali. | M33: =+OFFSET(F33,0,IF(F33,4,5)) -> Di che entità sono eventuali passività potenziali?
E34: Non esistono rischi derivanti dalle garanzie concesse? | F34: FALSE | H34: Per quanto concerne le garanzie concesse a terzi non si evidenziano rischi meritevoli di menzione. | I34: Esistono rilevanti rischi per garanzie concesse a terzi. | J34: Aggiungere eventuali commenti | K34: Descrivere e precisare se ne è stato tenuto conto a livello di fondi rischi. | L34: =+OFFSET(F34,0,IF(F34,2,3)) -> Esistono rilevanti rischi per garanzie concesse a terzi. | M34: =+OFFSET(F34,0,IF(F34,4,5)) -> Descrivere e precisare se ne è stato tenuto conto a livello di fondi rischi.
C35: 2.7 | E35: Esiste l'organo di controllo o il revisore legale? | F35: FALSE | H35: L'organo di controllo o il revisore legale è composto da | I35: Non è stato nominato l'organo di controllo o il revisore legale. | J35: Indicare i nominativi e eventuali | K35: Chiarire le ragioni. | L35: =+OFFSET(F35,0,IF(F35,2,3)) -> Non è stato nominato l'organo di controllo o il revisore legale. | M35: =+OFFSET(F35,0,IF(F35,4,5)) -> Chiarire le ragioni.
C36: 2.8 | E36: Sono disponibili informazioni sull'andamento corrente in termini di ricavi, portafoglio ordini, costi e flussi finanziari? | F36: FALSE | H36: Sono disponibili informazioni sull'andamento corrente in termini di ricavi, portafoglio ordini, costi e flussi finanziari. | I36: Non sono disponibili informazioni sull'andamento corrente in termini di ricavi, portafoglio ordini, costi e flussi finanziari. | J36: Quali informazioni? | K36: Aggiungere eventuali commenti | L36: =+OFFSET(F36,0,IF(F36,2,3)) -> Non sono disponibili informazioni sull'andamento corrente in termini di ricavi, portafoglio ordini, costi e flussi finanziari. | M36: =+OFFSET(F36,0,IF(F36,4,5)) -> Aggiungere eventuali commenti
E37: È disponibile un confronto con lo stesso periodo del precedente esercizio? | F37: FALSE | H37: È disponibile un confronto con lo stesso periodo del precedente esercizio. | I37: È disponibile un confronto con lo stesso periodo del precedente esercizio. | J37: Che tipo di confronto? | K37: Aggiungere eventuali commenti | L37: =+OFFSET(F37,0,IF(F37,2,3)) -> È disponibile un confronto con lo stesso periodo del precedente esercizio. | M37: =+OFFSET(F37,0,IF(F37,4,5)) -> Aggiungere eventuali commenti

Sheet SEZIONI 3-4
A3: 3 | D3: Individuazione delle strategie di intervento atte a prevenire e rimuovere le cause della crisi | H3: Frase VERO | I3: Frase FALSO | J3: Frase suggerimento per commenti in caso di risposta positiva | K3: Frase suggerimento per commenti in caso di risposta negativa | L3: Frase Completa | M3: Suggerimento
B4: 3.1.1 | E4: L’imprenditore non percepisce uno stato di crisi o uno squilibrio patrimoniale o economico-finanziario che la rende probabile? | F4: FALSE | H4: L’assetto contabile, amministrativo e contabile non ha rilevato elementi tali da far percepire uno stato di crisi o di squilibrio patrimoniale e/o economico finanziario. | I4: Esistono alcune evidenze tali da far presagire uno stato di crisi e o uno squilibrio economico patrimoniale. | J4: Aggiungere eventuali commenti | K4: Specificare | L4: =+OFFSET(F4,0,IF(F4,2,3)) -> Esistono alcune evidenze tali da far presagire uno stato di crisi e o uno squilibrio economico patrimoniale. | M4: =+OFFSET(F4,0,IF(F4,4,5)) -> Specificare
B5: 3.1.2 | E5: Quali sono le manifestazioni esteriori di tale stato
E6: lo squilibrio percepito è di carattere: | F6: =+COUNTIF(F7:F9,TRUE)>0 -> FALSE | I6: {=IF(F6, +CONCATENATE("Per quanto concerne lo stato di crisi, ",E6, IF(F7,E7&N7,""), IF(F8,E8&N8,""), IF(F9,E9&N9,""),".")& IF(F11,CONCATENATE(AC,E11, IF(F12,E12&N12,""), IF(F13,E13&N13,""), IF(F14,E14&N14,""), IF(F15,E15&N15,""), IF(F16,E16&N16,""), IF(F17,E17&N17,""), IF(F18,E18&N18,""), IF(F19,E19&N19,""), IF(F20,E20&N20,""), IF(F21,E21&N21,""))&pu&AC&E10,""),"")}
E7: economico | F7: FALSE | N7: =+IF( COUNTIF(F8:$F$9,TRUE)=1," e ", IF( COUNTIF(F8:$F$9,TRUE)>1,", ",""))
E8: patrimoniale | F8: FALSE | N8: =+IF( COUNTIF(F9:$F$9,TRUE)=1," e ", IF( COUNTIF(F9:$F$9,TRUE)>1,", ",""))
E9: finanziario | F9: FALSE
C10: Ulteriori Commenti | E10: altro (specificare) | F10: =+IF(E10>"",TRUE,FALSE) -> TRUE
E11: Sono peggiorati rispetto all'anno precedente i seguenti indicatori: | F11: =+COUNTIF(F12:F21,TRUE)>0 -> FALSE
E12: fatturato | F12: FALSE | N12: =+IF( COUNTIF(F13:$F$21,TRUE)=1," e ", IF( COUNTIF(F13:$F$21,TRUE)>1,", ",""))
E13: margine di contribuzione | F13: FALSE | N13: =+IF( COUNTIF(F14:$F$21,TRUE)=1," e ", IF( COUNTIF(F14:$F$21,TRUE)>1,", ",""))
E14: margine di contribuzione % | F14: FALSE | N14: =+IF( COUNTIF(F15:$F$21,TRUE)=1," e ", IF( COUNTIF(F15:$F$21,TRUE)>1,", ",""))
E15: EBITDA | F15: FALSE | N15: =+IF( COUNTIF(F16:$F$21,TRUE)=1," e ", IF( COUNTIF(F16:$F$21,TRUE)>1,", ",""))
E16: risultato ante imposte | F16: FALSE | N16: =+IF( COUNTIF(F17:$F$21,TRUE)=1," e ", IF( COUNTIF(F17:$F$21,TRUE)>1,", ",""))
E17: grado di indipendenza finanziaria (PN/Totale Attivo) | F17: FALSE | N17: =+IF( COUNTIF(F18:$F$21,TRUE)=1," e ", IF( COUNTIF(F18:$F$21,TRUE)>1,", ",""))
E18: copertura delle immobilizzazioni | F18: FALSE | N18: =+IF( COUNTIF(F19:$F$21,TRUE)=1," e ", IF( COUNTIF(F19:$F$21,TRUE)>1,", ",""))
E19: incidenza delle passività a breve | F19: FALSE | N19: =+IF( COUNTIF(F20:$F$21,TRUE)=1," e ", IF( COUNTIF(F20:$F$21,TRUE)>1,", ",""))
E20: capitale circolante netto | F20: FALSE | N20: =+IF( COUNTIF(F21:$F$21,TRUE)=1," e ", IF( COUNTIF(F21:$F$21,TRUE)>1,", ",""))
E21: posizione finanziaria netta | F21: FALSE
E22: Si sono verificati i seguenti eventi. | I22: {=IF(OR(F23,F29,F38),+"Lo stato di crisi ha causato anomalie:"&CHAR(10)& IF(COUNTIF(F24:F28,TRUE)>0,CHAR(10)&p&"da un punto di vista commerciale"&IF(OR(F29,F38),";",pu),"")& IF(COUNTIF(F30:F36,TRUE)>0,CHAR(10)&p&"nei rapporti con le banche"&IF(F38,";",pu),"")& IF(COUNTIF(F39:F42,TRUE)>0,CHAR(10)&p&"da un punto di vista gestionale"&pu,""),"")} -> Lo stato di crisi ha causato anomalie: • da un punto di vista commerciale;
E23: Da un punto di vista commerciale | F23: =+COUNTIF(F24:F28,TRUE)>0 -> TRUE
E24: mancati rilevanti pagamenti a fornitori | F24: FALSE | I24: {=+IF(F23,E23&" si sono verificati "& IF(F24,E24&N24,"")& IF(F25,E25&N25,"")& IF(F26,E26&N26,"")& IF(F27,E27&N27,"")& IF(F28,E28&N28,"")& pu&AC,"")} -> Da un punto di vista commerciale si sono verificati altro (specificare). | N24: =+IF( COUNTIF(F25:$F$28,TRUE)=1," e ", IF( COUNTIF(F25:$F$28,TRUE)>1,", ","")) -> e
E25: significativa rinegoziazione delle condizioni di pagamento | F25: FALSE | N25: =+IF( COUNTIF(F26:$F$28,TRUE)=1," e ", IF( COUNTIF(F26:$F$28,TRUE)>1,", ","")) -> e
E26: pagamento di penali rilevanti per mancate consegne | F26: FALSE | N26: =+IF( COUNTIF(F27:$F$28,TRUE)=1," e ", IF( COUNTIF(F27:$F$28,TRUE)>1,", ","")) -> e
E27: svendite rilevanti di materiale | F27: FALSE | N27: =+IF( COUNTIF(F28:$F$28,TRUE)=1," e ", IF( COUNTIF(F28:$F$28,TRUE)>1,", ","")) -> e
C28: Indicare eventuali altri eventi | E28: altro (specificare) | F28: =+IF(E28>"",TRUE,FALSE) -> TRUE
E29: Nei rapporti con le banche | F29: =+COUNTIF(F30:F37,TRUE)>0 -> TRUE | I29: {=+IF(F29,E29&" sono state rilevate "& IF(F30,E30&N30,"")& IF(F31,E31&N31,"")& IF(F32,E32&N32,"")& IF(F33,E33&N33,"")& IF(F34,E34&N34,"")& IF(F35,E35&N35,"")& IF(F36,E36&N36,"")& IF(F37,E37&N37,"")& pu&AC,"")} -> Nei rapporti con le banche sono state rilevate altro (specificare).
E30: segnalazioni inframensili negative | F30: FALSE | N30: =+IF( COUNTIF(F31:$F$37,TRUE)=1," e ", IF( COUNTIF(F31:$F$37,TRUE)>1,", ","")) -> e
E31: sofferenze | F31: FALSE | N31: =+IF( COUNTIF(F32:$F$37,TRUE)=1," e ", IF( COUNTIF(F32:$F$37,TRUE)>1,", ","")) -> e
E32: sconfini rilevanti entro i 90 giorni | F32: FALSE | N32: =+IF( COUNTIF(F33:$F$37,TRUE)=1," e ", IF( COUNTIF(F33:$F$37,TRUE)>1,", ","")) -> e
E33: sconfini oltre i 90 giorni | F33: FALSE | N33: =+IF( COUNTIF(F34:$F$37,TRUE)=1," e ", IF( COUNTIF(F34:$F$37,TRUE)>1,", ","")) -> e
E34: escussione di garanzie di terzi | F34: FALSE | N34: =+IF( COUNTIF(F35:$F$37,TRUE)=1," e ", IF( COUNTIF(F35:$F$37,TRUE)>1,", ","")) -> e
E35: escussione di nostre garanzie a terzi | F35: FALSE | N35: =+IF( COUNTIF(F36:$F$37,TRUE)=1," e ", IF( COUNTIF(F36:$F$37,TRUE)>1,", ","")) -> e
E36: aumento anomalo dei crediti impagati | F36: FALSE | N36: =+IF( COUNTIF(F37:$F$37,TRUE)=1," e ", IF( COUNTIF(F37:$F$37,TRUE)>1,", ","")) -> e
C37: Indicare eventuali altri eventi | E37: altro (specificare) | F37: =+IF(E37>"",TRUE,FALSE) -> TRUE
E38: Da un punto di vista gestionale si segnala | F38: =+COUNTIF(F39:F43,TRUE)>0 -> TRUE | I38: {=+IF(F38,E38& IF(F39,E39&N39,"")& IF(F40,E40&N40,"")& IF(F41,E41&N41,"")& IF(F42,E42&N42,"")& IF(F43,E43&N43,"")& pu&AC,"")} -> Da un punto di vista gestionale si segnala altro (specificare).
E39: la perdita di membri della direzione con responsabilità strategiche senza una loro sostituzione | F39: FALSE | N39: =+IF( COUNTIF(F40:$F$43,TRUE)=1," e ", IF( COUNTIF(F40:$F$43,TRUE)>1,", ","")) -> e
E40: la perdita di clienti o commesse importanti | F40: FALSE | N40: =+IF( COUNTIF(F41:$F$43,TRUE)=1," e ", IF( COUNTIF(F41:$F$43,TRUE)>1,", ","")) -> e
E41: controversie rilevanti con il personale | F41: FALSE | N41: =+IF( COUNTIF(F43:$F$43,TRUE)=1," e ", IF( COUNTIF(F43:$F$43,TRUE)>1,", ","")) -> e
E42: comparsa di concorrenti ostili e/o nuovi entranti che rischiano di ridurre ulteriormente le quote di mercato | F42: FALSE | N42: =+IF( COUNTIF(F$43:$F43,TRUE)=1," e ", IF( COUNTIF(F$43:$F43,TRUE)>1,", ","")) -> e
...

Sheet SEZIONI 5-6
A5: 5 | D5: Il risanamento del debito | H5: Frase VERO | I5: Frase FALSO | J5: Frase suggerimento per commenti in caso di risposta positiva | K5: Frase suggerimento per commenti in caso di risposta negativa | L5: Frase Completa | M5: Suggerimento
B6: 5.1 | E6: L’impresa, alla luce del par. 4 della presente Sezione, è in grado in futuro di generare risorse al servizio del debito? | F6: FALSE | H6: L’impresa è in grado in futuro di generare risorse al servizio del debito. | I6: L’impresa non è in grado in futuro di generare risorse al servizio del debito. | J6: Indicare da dove provengono dette risorse. | K6: Indicare cosa si intende fare per sostenere il piano in altro modo | L6: =+OFFSET(F6,0,IF(F6,2,3)) -> L’impresa non è in grado in futuro di generare risorse al servizio del debito. | M6: =+OFFSET(F6,0,IF(F6,4,5)) -> Indicare cosa si intende fare per sostenere il piano in altro modo
E7: Il risultato delle proiezioni finanziarie di cui al punto 4.10 della presente Sezione tende ad essere positivo? | F7: FALSE | H7: Il risultato delle proiezioni finanziarie tende ad essere positivo. | I7: Il risultato delle proiezioni finanziarie tende ad essere negativo. | J7: Aggiungere eventuali commenti | K7: Aggiungere eventuali commenti | L7: =+OFFSET(F7,0,IF(F7,2,3)) -> Il risultato delle proiezioni finanziarie tende ad essere negativo. | M7: =+OFFSET(F7,0,IF(F7,4,5)) -> Aggiungere eventuali commenti
B8: 5.2 | E8: Il piano tiene conto, anche attraverso prove di resistenza (stress test), dei fattori di rischio e di incertezza ai quali è maggiormente esposta l’impresa? | F8: FALSE | H8: Il piano tiene conto, anche attraverso prove di resistenza (stress test), dei fattori di rischio e di incertezza ai quali è maggiormente esposta l’impresa. | I8: Il piano non tiene conto, anche attraverso prove di resistenza (stress test), dei fattori di rischio e di incertezza ai quali è maggiormente esposta l’impresa. | J8: Indicare i risultati dello stress test | K8: Indicare le ragioni che hanno condotto i relatori a non sottoporre il piano allo stress test | L8: =+OFFSET(F8,0,IF(F8,2,3)) -> Il piano non tiene conto, anche attraverso prove di resistenza (stress test), dei fattori di rischio e di incertezza ai quali è maggiormente esposta l’impresa. | M8: =+OFFSET(F8,0,IF(F8,4,5)) -> Indicare le ragioni che hanno condotto i relatori a non sottoporre il piano allo stress test
E9: Tali prove sono coerenti con i rischi emersi ad esito dell’intervista delle diverse funzioni aziendali avendo comunque riguardo alle prospettive di mercato? | F9: FALSE | H9: I test effettuati sono coerenti con i rischi emersi ad esito dell’intervista delle diverse funzioni aziendali avendo comunque riguardo alle prospettive di mercato. | I9: I test effettuati sono coerenti con i rischi emersi ad esito dell’intervista delle diverse funzioni aziendali avendo comunque riguardo alle prospettive di mercato. | J9: Aggiungere eventuali commenti | K9: Aggiungere eventuali commenti | L9: =+OFFSET(F9,0,IF(F9,2,3)) -> I test effettuati sono coerenti con i rischi emersi ad esito dell’intervista delle diverse funzioni aziendali avendo comunque riguardo alle prospettive di mercato. | M9: =+OFFSET(F9,0,IF(F9,4,5)) -> Aggiungere eventuali commenti
B10: 5.3 | E10: La generazione di flussi positivi al servizio del debito dipende solo dalle iniziative industriali? | F10: FALSE | H10: La generazione di flussi positivi al servizio del debito dipende solo dalle iniziative industriali. | I10: La generazione di flussi positivi al servizio del debito non dipende solo dalle iniziative industriali. | J10: Aggiungere eventuali commenti | K10: Aggiungere eventuali commenti | L10: =+OFFSET(F10,0,IF(F10,2,3)) -> La generazione di flussi positivi al servizio del debito non dipende solo dalle iniziative industriali. | M10: =+OFFSET(F10,0,IF(F10,4,5)) -> Aggiungere eventuali commenti
B11: 5.4 | E11: A quanto ammonta il debito che deve essere servito nei singoli anni del piano? | F11: FALSE | I11: =+IF(F11,"Il debito che deve essere servito nei singoli anni del piano ammonta a"&s&E12&pu,"")
C12: Ulteriori commenti | E12: A quanto ammonta il debito che deve essere servito nei singoli anni del piano? | F12: FALSE
B13: 5.5 | E13: Come l’imprenditore intende fronteggiare il debito che deve essere coperto nei diversi anni attraverso i flussi al servizio dello stesso? | F13: FALSE | I13: =+IF(F13,"L’imprenditore intende fronteggiare il debito che deve essere coperto nei diversi anni attraverso i flussi al servizio dello stesso"&s&E14&pu,"")
C14: Ulteriori commenti | E14: indicare come l'imprenditore intende fronteggiare | F14: FALSE
H15: Frase VERO | I15: Frase FALSO | J15: Frase suggerimento per commenti in caso di risposta positiva | K15: Frase suggerimento per commenti in caso di risposta negativa | L15: Frase Completa | M15: Suggerimento
B16: 5.6 | E16: Le proposte consentono, in via prognostica, il rispetto del minimo legale del capitale sociale al momento della conclusione dell’accordo, fatte salve le disposizioni speciali? | F16: FALSE | H16: Le proposte consentono, in via prognostica, il rispetto del minimo legale del capitale sociale al momento della conclusione dell’accordo, fatte salve le disposizioni speciali. | I16: Le proposte non consentono, in via prognostica, il rispetto del minimo legale del capitale sociale al momento della conclusione dell’accordo, fatte salve le disposizioni speciali. | J16: Aggiungere eventuali commenti | K16: Aggiungere eventuali commenti | L16: =+OFFSET(F16,0,IF(F16,2,3)) -> Le proposte non consentono, in via prognostica, il rispetto del minimo legale del capitale sociale al momento della conclusione dell’accordo, fatte salve le disposizioni speciali. | M16: =+OFFSET(F16,0,IF(F16,4,5)) -> Aggiungere eventuali commenti
A18: 6 | D18: In caso di gruppi di imprese | H18: Frase VERO | I18: Frase FALSO | J18: Frase suggerimento per commenti in caso di risposta positiva | K18: Frase suggerimento per commenti in caso di risposta negativa | L18: Frase Completa | M18: Suggerimento
B19: 6.1 | E19: Il piano è redatto per le singole imprese? | F19: FALSE | H19: Il piano è redatto per le singole imprese. | I19: Il piano è redatto per le singole imprese. | J19: Aggiungere eventuali commenti | K19: Aggiungere eventuali commenti | L19: =+OFFSET(F19,0,IF(F19,2,3)) -> Il piano è redatto per le singole imprese. | M19: =+OFFSET(F19,0,IF(F19,4,5)) -> Aggiungere eventuali commenti
B20: 6.2 | E20: Il piano dà evidenza dei rapporti economici, finanziari e patrimoniali infragruppo? | F20: FALSE | H20: Il piano dà evidenza dei rapporti economici, finanziari e patrimoniali infragruppo. | I20: Il piano non dà evidenza dei rapporti economici, finanziari e patrimoniali infragruppo. | J20: Aggiungere eventuali commenti | K20: Aggiungere eventuali commenti | L20: =+OFFSET(F20,0,IF(F20,2,3)) -> Il piano non dà evidenza dei rapporti economici, finanziari e patrimoniali infragruppo. | M20: =+OFFSET(F20,0,IF(F20,4,5)) -> Aggiungere eventuali commenti
B21: 6.3 | E21: Vi sono altre imprese del gruppo che presentano difficoltà economico-finanziarie o patrimoniali? Come siintende agire per affrontarle? | F21: FALSE | H21: Vi sono altre imprese del gruppo che presentano difficoltà economico-finanziarie o patrimoniali? | I21: Non vi sono altre imprese del gruppo che presentano difficoltà economico-finanziarie o patrimoniali? | J21: Aggiungere eventuali commenti | K21: Aggiungere eventuali commenti | L21: =+OFFSET(F21,0,IF(F21,2,3)) -> Non vi sono altre imprese del gruppo che presentano difficoltà economico-finanziarie o patrimoniali? | M21: =+OFFSET(F21,0,IF(F21,4,5)) -> Aggiungere eventuali commenti
F22: FALSE | I22: =+IF(F22,"L’imprenditore intende affrontarle"&s&E23&pu,"")
C23: Come si intende agire per affrontarle? | E23: indicare come l'imprenditore intende affrontarle | F23: FALSE
B24: 6.4 | E24: Esistono altre imprese del gruppo la cui continuità aziendale dipende da quella dell’impresa? | F24: FALSE | I24: =+IF(F24,"Le altre imprese del gruppo la cui continuità aziendale dipende da quella dell’impresa sono"&s&E25&pu,"")
C25: Quali sono le imprese e perché? | E25: indicare quali sono le altre imprese del gruppo la cui continuità aziendale dipende da quella dell'impresa | F25: FALSE
B26: 6.5 | E26: Le operazioni infragruppo previste nel piano possono arrecare un pregiudizio per i creditori di un’altra impresa del gruppo? | F26: FALSE | H26: Le operazioni infragruppo previste nel piano possono arrecare un pregiudizio per i creditori di un’altra impresa del gruppo. | I26: Le operazioni infragruppo previste nel piano non possono arrecare un pregiudizio per i creditori di un’altra impresa del gruppo. | J26: Aggiungere eventuali commenti | K26: Aggiungere eventuali commenti | L26: =+OFFSET(F26,0,IF(F26,2,3)) -> Le operazioni infragruppo previste nel piano non possono arrecare un pregiudizio per i creditori di un’altra impresa del gruppo. | M26: =+OFFSET(F26,0,IF(F26,4,5)) -> Aggiungere eventuali commenti
C27: Specificare | E27: indicare quali sono le altre imprese del gruppo la cui continuità aziendale dipende da quella dell'impresa

Sheet Relazione
L2: RELAZIONE FINALE
L3: =+'SEZIONI 1-2'!$C$3 -> ALFA S.R.L
A4: SEZIONE 1-2 | L4: =+'SEZIONI 1-2'!C5 -> 45253
B5: =+'SEZIONI 1-2'!$D$8 -> Il requisito dell’organizzazione dell’impresa | I5: =+B5 -> Il requisito dell’organizzazione dell’impresa | L5: =+I5 -> Il requisito dell’organizzazione dell’impresa
D6: =+'SEZIONI 1-2'!L9 -> L’impresa non dispone delle risorse chiave (umane e tecniche) per la conduzione dell’attività. | J6: =+CONCATENATE(D6, IF(D7>"",s&D7,"")) -> L’impresa non dispone delle risorse chiave (umane e tecniche) per la conduzione dell’attività. | L6: {=+CONCATENATE(J6,AC,J7,AC,J8,s,J9,s,J10,s,J11,AC,J12,AC,J13)} -> L’impresa non dispone delle risorse chiave (umane e tecniche) per la conduzione dell’attività. Da un punto di vista tecnico/economico, l’impresa non dispone delle competenze necessarie per le iniziative industriali che l’imprenditore intende adottare. Il monitoraggio dell'andamento aziendale appare inadeguato. I ricavi non sono controllati in maniera adeguata. Gli ordini non sono controllati in maniera adeguata. La posizione finanziaria netta non è costantemente monitorata. L'impresa non fa ancora ricorso a KPI che consentono valutazioni rapide e continue, non è in grado di individuare gli indicatori di produttività coerenti con il proprio modello di business ed il proprio settore di attività, e di raccogliere ulteriori informazioni per la valutazione dell’andamento tendenziale. L'impresa non dispone di un piano di tesoreria a 12 mesi. Non è in grado di predisporre un prospetto delle stime delle entrate e delle uscite finanziare almeno a 13 settimane, il cui scostamento con l’andamento corrente dovrà essere valutato a consuntivo.
C7: =+'SEZIONI 1-2'!M9 -> L’impresa come pensa di procurarsi tali risorse? | J7: =CONCATENATE(D8, IF(D9>"",s&D9,"")) -> Da un punto di vista tecnico/economico, l’impresa non dispone delle competenze necessarie per le iniziative industriali che l’imprenditore intende adottare.
D8: =+'SEZIONI 1-2'!L10 -> Da un punto di vista tecnico/economico, l’impresa non dispone delle competenze necessarie per le iniziative industriali che l’imprenditore intende adottare. | G8: =+CHAR(149)& " " -> • | J8: =+CONCATENATE(D10, IF(D11>"",s&D11,"")) -> Il monitoraggio dell'andamento aziendale appare inadeguato.
C9: =+'SEZIONI 1-2'!M10 -> Indicare le iniziative industriali per le quali l'impresa sia realisticamente in grado di disporre, eventualmente acquisendole sul mercato, delle competenze tecniche occorrenti: | J9: =+CONCATENATE(D12, IF(D13>"",s&D13,"")) -> I ricavi non sono controllati in maniera adeguata.
D10: =+'SEZIONI 1-2'!L11 -> Il monitoraggio dell'andamento aziendale appare inadeguato. | J10: =CONCATENATE(D14, IF(D15>"",s&D15,"")) -> Gli ordini non sono controllati in maniera adeguata.
C11: =+'SEZIONI 1-2'!M11 -> Indicare cosa intende fare per controllare la gestione | J11: =CONCATENATE(D16, IF(D17>"",(s&D17),"")) -> La posizione finanziaria netta non è costantemente monitorata.
D12: =+'SEZIONI 1-2'!L12 -> I ricavi non sono controllati in maniera adeguata. | J12: =CONCATENATE(D18, IF(D19>"",(s&D19),""),s,D20,IF(D21>"",CONCATENATE(s,D21),"")) -> L'impresa non fa ancora ricorso a KPI che consentono valutazioni rapide e continue, non è in grado di individuare gli indicatori di produttività coerenti con il proprio modello di business ed il proprio settore di attività, e di raccogliere ulteriori informazioni per la valutazione dell’andamento tendenziale.
C13: =+'SEZIONI 1-2'!M12 -> Indicare quale controllo viene fatto e come si intende intervenire per migliorare il sistema di controllo. | J13: =CONCATENATE(D22, IF(D23>"",CONCATENATE(s,D23),""),s,D24,IF(D25>"",CONCATENATE(s,D25),"")) -> L'impresa non dispone di un piano di tesoreria a 12 mesi. Non è in grado di predisporre un prospetto delle stime delle entrate e delle uscite finanziare almeno a 13 settimane, il cui scostamento con l’andamento corrente dovrà essere valutato a consuntivo.
D14: =+'SEZIONI 1-2'!L13 -> Gli ordini non sono controllati in maniera adeguata.
C15: =+'SEZIONI 1-2'!M13 -> Indicare quale controllo viene fatto e come si intende intervenire per migliorare il sistema di controllo. | I15: =+B26 -> Rilevazione della situazione contabile e dell’andamento corrente | L15: =+I15 -> Rilevazione della situazione contabile e dell’andamento corrente
D16: =+'SEZIONI 1-2'!L14 -> La posizione finanziaria netta non è costantemente monitorata. | J16: =CONCATENATE(D27, IF(D28>"",(s&D28),"")) -> L'ultima situazione redatta risale a oltre 120 giorni. | L16: {=+CONCATENATE(J16,s,J17,s,J18,s,J19,s,J20,s,J21,s,J22,AC,J23,AC,J24,AC,J25,AC,J26,AC,J27)} -> L'ultima situazione redatta risale a oltre 120 giorni. La situazione non è da considerarsi affidabile per quanto concerne la corretta rappresentazione della situazione debitoria dell'impresa. Il maggior contabile dei cespiti è superiore al valore di realizzo e a quello di mercato. Non esiste in azienda un prospetto recante l’anzianità dei crediti commerciali , non sono state analizzate le cause del ritardo di incasso tale da consentire una valutazione oggettiva dei rischi di perdite sui crediti e una stima prudente dei tempi di incasso. Non vi sono informazioni sufficienti per suddividere i crediti in base all'anzianità. Per gli scaduti che superano la fisiologia (tempi ordinari di pagamento, pur oltre la scadenza contrattuale, che caratterizzano il settore), la stima del momento dell’incasso non è da considerarsi sufficientemente prudente. Non è stato redatto alcun prospetto recante le rimanenze di magazzino con i tempi di movimentazione che consenta di individuare le giacenze oggetto di lenta rotazione. L'impresa non ha redatto un prospetto di riconciliazione tra la contabilità e quanto risultante dal certificato unico dei debiti tributari, dalla situazione debitoria complessiva dell’Agente della Riscossione. Ha redatto un prospetto di riconciliazione tra la contabilità e quanto risultante dal certificato unico dei debiti contributivi e assicurativi La Centrale rischi di Banca D'Italia non viene esaminata periodicamente e non riconciliata con la contabilità. L’azienda non ha tenuto conto delle passività potenziali. Esistono rilevanti rischi per garanzie concesse a terzi. Non è stato nominato l'organo di controllo o il revisore legale.
C17: =+'SEZIONI 1-2'!M14 -> Indicare quale controllo viene fatto e come si intende intervenire per migliorare il sistema di controllo. | J17: =CONCATENATE(D29, IF(D30>"",(s&D30),"")) -> La situazione non è da considerarsi affidabile per quanto concerne la corretta rappresentazione della situazione debitoria dell'impresa.
D18: =+'SEZIONI 1-2'!L15 -> L'impresa non fa ancora ricorso a KPI che consentono valutazioni rapide e continue, | J18: =CONCATENATE(D31, IF(D32>"",(s&D32),"")) -> Il maggior contabile dei cespiti è superiore al valore di realizzo e a quello di mercato.
C19: =+'SEZIONI 1-2'!M15 -> 0 | J19: =CONCATENATE(D33, IF(D34,(s&D34),""),s,D35,IF(D36>"",(s&D36),"")) -> Non esiste in azienda un prospetto recante l’anzianità dei crediti commerciali , non sono state analizzate le cause del ritardo di incasso tale da consentire una valutazione oggettiva dei rischi di perdite sui crediti e una stima prudente dei tempi di incasso.
D20: =+'SEZIONI 1-2'!L16 -> non è in grado di individuare gli indicatori di produttività coerenti con il proprio modello di business ed il proprio settore di attività, e di raccogliere ulteriori informazioni per la valutazione dell’andamento tendenziale. | J20: =CONCATENATE(D37,IF(D38>"",(s&D38),"")) -> Non vi sono informazioni sufficienti per suddividere i crediti in base all'anzianità.
C21: =+'SEZIONI 1-2'!M16 -> Indicare se e quando intende adottare i KPI, quale metodologia intende adottare (BSC, BMC, KPI, ecc) e quali controlli avvengono per misurare la produttività aziendale. | J21: =CONCATENATE(D39,IF(D40>"",(s&D40),"")) -> Per gli scaduti che superano la fisiologia (tempi ordinari di pagamento, pur oltre la scadenza contrattuale, che caratterizzano il settore), la stima del momento dell’incasso non è da considerarsi sufficientemente prudente.
D22: =+'SEZIONI 1-2'!L17 -> L'impresa non dispone di un piano di tesoreria a 12 mesi. | J22: =CONCATENATE(D41,IF(D42>"",(s&D42),"")) -> Non è stato redatto alcun prospetto recante le rimanenze di magazzino con i tempi di movimentazione che consenta di individuare le giacenze oggetto di lenta rotazione.
C23: =+'SEZIONI 1-2'!M17 -> Spiegare le motivazioni per le quali non è stato redatto un piano di tesoreria e come si intende rimuovere gli ostacoli. | J23: =CONCATENATE(D43, IF(D44>"",(s&D44),""),s,D45,IF(D46>"",(s&D46),"")) -> L'impresa non ha redatto un prospetto di riconciliazione tra la contabilità e quanto risultante dal certificato unico dei debiti tributari, dalla situazione debitoria complessiva dell’Agente della Riscossione. Ha redatto un prospetto di riconciliazione tra la contabilità e quanto risultante dal certificato unico dei debiti contributivi e assicurativi
D24: =+'SEZIONI 1-2'!L18 -> Non è in grado di predisporre un prospetto delle stime delle entrate e delle uscite finanziare almeno a 13 settimane, il cui scostamento con l’andamento corrente dovrà essere valutato a consuntivo. | J24: =CONCATENATE(D47, IF(D48>"",(s&D48),""),s,D49,IF(D50>"",(s&D50),"")) -> La Centrale rischi di Banca D'Italia non viene esaminata periodicamente e non riconciliata con la contabilità.
C25: =+'SEZIONI 1-2'!M18 -> Spiegare le motivazioni per le quali non è stato redatto il prospetto e come si intende rimuovere gli ostacoli. | J25: =CONCATENATE(D51,IF(D52>"",(s&D52),"")) -> L’azienda non ha tenuto conto delle passività potenziali.
B26: =+'SEZIONI 1-2'!$D$20 -> Rilevazione della situazione contabile e dell’andamento corrente | J26: =CONCATENATE(D53,IF(D54>"",(s&D54),"")) -> Esistono rilevanti rischi per garanzie concesse a terzi.
D27: =+'SEZIONI 1-2'!L21 -> L'ultima situazione redatta risale a oltre 120 giorni. | J27: =CONCATENATE(D55,IF(D56>"",(s&D56),"")) -> Non è stato nominato l'organo di controllo o il revisore legale.
C28: =+'SEZIONI 1-2'!M21 -> Indicare i tempi previsti per una situazione aggiornata
D29: =+'SEZIONI 1-2'!L22 -> La situazione non è da considerarsi affidabile per quanto concerne la corretta rappresentazione della situazione debitoria dell'impresa. | L29: =+I32 -> Individuazione delle strategie di intervento atte a prevenire e rimuovere le cause della crisi
C30: =+'SEZIONI 1-2'!M22 -> Indicare le cause che impediscono un'affidabilità della situazione debitoria. | L30: {=+CONCATENATE(J33,s,J34,s,J35,AC,J36,s,J37,s,J38,s,J39,s,J40,s,J41,s,J42,AC,J43,AC,J44,s,J45,s,J46,s,J47,s,J48,s,J49,AC,J50,s,J51,s,J52,s,J53,s,J54,AC,J55)} -> Esistono alcune evidenze tali da far presagire uno stato di crisi e o uno squilibrio economico patrimoniale. Lo stato di crisi ha causato anomalie: • da un punto di vista commerciale; Da un punto di vista commerciale si sono verificati altro (specificare). Nei rapporti con le banche sono state rilevate altro (specificare). Da un punto di vista gestionale si segnala altro (specificare). La situazione di difficoltà descritta ha causato un debito da ristrutturare (per mancati pagamenti e/o richieste di rientro) per altro (specificare). Sul lato delle iniziative dei creditori si segnalano altro (specificare). Tenuto conto delle manifestazioni, le cause sono: altro (specificare). L’organo di controllo ed il revisore, quando in carica, non ritengono che il quadro fornito dall’imprenditore sia completo e adeguato. L'impresa non ha ancora individuato le strategie di intervento e le iniziative industriali che intende adottare. Non esistono strategie di successo adottate dalla concorrenza. Tali strategie non sono adottabili dall'impresa. L’impresa non dispone delle capacità e delle competenze manageriali per realizzare le iniziative industriali. Per quanto concerne i tempi e gli effetti in termini di ricavi, di costi e di investimenti delle iniziative da adottare Indicare i tempi e i relativi effetti in termini di ricavi, di costi e di invesgtimenti delle iniziative da adottare. Le relative funzioni aziendali responsabili sono Indicare quali sono le relative funzioni aziendali responsabili. Non sono prospettabili iniziative alternative nel caso in cui le iniziative dovessero dimostrarsi inefficaci e si manifestassero scostamenti tra gli obiettivi pianificati e quelli raggiunti. Non sono mai stati predisposti piani aziendali. Il piano non è coerente con i piani redatti in precedenza e non vi sono differenze significative. Il piano non appare credibile. Non è fondato su intenzioni strategiche chiare e razionali, condivisibili da parte di un lettore informato quale è l’esperto, coerenti con la situazione di fatto dell’impresa e del contesto in cui opera. Le strategie di intervento e le iniziative industriali individuate dall’imprenditore non appaiono appropriate per il superamento delle cause della crisi.
D31: =+'SEZIONI 1-2'!L23 -> Il maggior contabile dei cespiti è superiore al valore di realizzo e a quello di mercato.
C32: =+'SEZIONI 1-2'!M23 -> L'impresa intende quanto meno appostare con prudenza adeguati fondi rischi e fondi per l’adeguamento delle attività e delle passività? | I32: =+B63 -> Individuazione delle strategie di intervento atte a prevenire e rimuovere le cause della crisi
D33: =+'SEZIONI 1-2'!L24 -> Non esiste in azienda un prospetto recante l’anzianità dei crediti commerciali | J33: =CONCATENATE(D64,IF(D65>"",(s&D65),"")) -> Esistono alcune evidenze tali da far presagire uno stato di crisi e o uno squilibrio economico patrimoniale.
C34: =+'SEZIONI 1-2'!M24 -> 0 | J34: =CONCATENATE(D66,IF(D67>"",(s&D67),""))
D35: =+'SEZIONI 1-2'!L25 -> , non sono state analizzate le cause del ritardo di incasso tale da consentire una valutazione oggettiva dei rischi di perdite sui crediti e una stima prudente dei tempi di incasso. | J35: =CONCATENATE(D68,IF(D69>"",(s&D69),"")) -> Lo stato di crisi ha causato anomalie: • da un punto di vista commerciale;
C36: =+'SEZIONI 1-2'!M25 -> Indicare eventuali interventi in termini di credit management | J36: =CONCATENATE(D70,IF(D71>"",(s&D71),"")) -> Da un punto di vista commerciale si sono verificati altro (specificare).
D37: =+'SEZIONI 1-2'!L26 -> Non vi sono informazioni sufficienti per suddividere i crediti in base all'anzianità. | J37: =CONCATENATE(D72,IF(D73>"",(s&D73),"")) -> Nei rapporti con le banche sono state rilevate altro (specificare).
C38: =+'SEZIONI 1-2'!M26 -> Indicare eventuali interventi in termini di credit management | J38: =CONCATENATE(D74,IF(D75>"",(s&D75),"")) -> Da un punto di vista gestionale si segnala altro (specificare).
D39: =+'SEZIONI 1-2'!L27 -> Per gli scaduti che superano la fisiologia (tempi ordinari di pagamento, pur oltre la scadenza contrattuale, che caratterizzano il settore), la stima del momento dell’incasso non è da considerarsi sufficientemente prudente. | J39: =CONCATENATE(D76,IF(D77>"",(s&D77),"")) -> La situazione di difficoltà descritta ha causato un debito da ristrutturare (per mancati pagamenti e/o richieste di rientro) per altro (specificare).
C40: =+'SEZIONI 1-2'!M27 -> Quali elementi non sono valutati con la dovuta prudenza? | J40: =CONCATENATE(D78,IF(D79>"",(s&D79),"")) -> Sul lato delle iniziative dei creditori si segnalano altro (specificare).
D41: =+'SEZIONI 1-2'!L28 -> Non è stato redatto alcun prospetto recante le rimanenze di magazzino con i tempi di movimentazione che consenta di individuare le giacenze oggetto di lenta rotazione. | J41: =CONCATENATE(D80,IF(D81>"",(s&D81),"")) -> Tenuto conto delle manifestazioni, le cause sono: altro (specificare).
...

Sheet Relazione Compatta (solo 365)
A4: Relazione in formato compatto (Disponibile solo con Excel 365)
A5: {=+_xlfn._xlws.FILTER(Relazione!L3:L99,(Relazione!L3:L99)>0)} -> ALFA S.R.L
A6: 45253
A7: Il requisito dell’organizzazione dell’impresa
A8: L’impresa non dispone delle risorse chiave (umane e tecniche) per la conduzione dell’attività. Da un punto di vista tecnico/economico, l’impresa non dispone delle competenze necessarie per le iniziative industriali che l’imprenditore intende adottare. Il monitoraggio dell'andamento aziendale appare inadeguato. I ricavi non sono controllati in maniera adeguata. Gli ordini non sono controllati in maniera adeguata. La posizione finanziaria netta non è costantemente monitorata. L'impresa non fa ancora ricorso a KPI che consentono valutazioni rapide e continue, non è in grado di individuare gli indicatori di produttività coerenti con il proprio modello di business ed il proprio settore di attività, e di raccogliere ulteriori informazioni per la valutazione dell’andamento tendenziale. L'impresa non dispone di un piano di tesoreria a 12 mesi. Non è in grado di predisporre un prospetto delle stime delle entrate e delle uscite finanziare almeno a 13 settimane, il cui scostamento con l’andamento corrente dovrà essere valutato a consuntivo.
A9: Rilevazione della situazione contabile e dell’andamento corrente
A10: L'ultima situazione redatta risale a oltre 120 giorni. La situazione non è da considerarsi affidabile per quanto concerne la corretta rappresentazione della situazione debitoria dell'impresa. Il maggior contabile dei cespiti è superiore al valore di realizzo e a quello di mercato. Non esiste in azienda un prospetto recante l’anzianità dei crediti commerciali , non sono state analizzate le cause del ritardo di incasso tale da consentire una valutazione oggettiva dei rischi di perdite sui crediti e una stima prudente dei tempi di incasso. Non vi sono informazioni sufficienti per suddividere i crediti in base all'anzianità. Per gli scaduti che superano la fisiologia (tempi ordinari di pagamento, pur oltre la scadenza contrattuale, che caratterizzano il settore), la stima del momento dell’incasso non è da considerarsi sufficientemente prudente. Non è stato redatto alcun prospetto recante le rimanenze di magazzino con i tempi di movimentazione che consenta di individuare le giacenze oggetto di lenta rotazione. L'impresa non ha redatto un prospetto di riconciliazione tra la contabilità e quanto risultante dal certificato unico dei debiti tributari, dalla situazione debitoria complessiva dell’Agente della Riscossione. Ha redatto un prospetto di riconciliazione tra la contabilità e quanto risultante dal certificato unico dei debiti contributivi e assicurativi La Centrale rischi di Banca D'Italia non viene esaminata periodicamente e non riconciliata con la contabilità. L’azienda non ha tenuto conto delle passività potenziali. Esistono rilevanti rischi per garanzie concesse a terzi. Non è stato nominato l'organo di controllo o il revisore legale.
A11: Individuazione delle strategie di intervento atte a prevenire e rimuovere le cause della crisi
A12: Esistono alcune evidenze tali da far presagire uno stato di crisi e o uno squilibrio economico patrimoniale. Lo stato di crisi ha causato anomalie: • da un punto di vista commerciale; Da un punto di vista commerciale si sono verificati altro (specificare). Nei rapporti con le banche sono state rilevate altro (specificare). Da un punto di vista gestionale si segnala altro (specificare). La situazione di difficoltà descritta ha causato un debito da ristrutturare (per mancati pagamenti e/o richieste di rientro) per altro (specificare). Sul lato delle iniziative dei creditori si segnalano altro (specificare). Tenuto conto delle manifestazioni, le cause sono: altro (specificare). L’organo di controllo ed il revisore, quando in carica, non ritengono che il quadro fornito dall’imprenditore sia completo e adeguato. L'impresa non ha ancora individuato le strategie di intervento e le iniziative industriali che intende adottare. Non esistono strategie di successo adottate dalla concorrenza. Tali strategie non sono adottabili dall'impresa. L’impresa non dispone delle capacità e delle competenze manageriali per realizzare le iniziative industriali. Per quanto concerne i tempi e gli effetti in termini di ricavi, di costi e di investimenti delle iniziative da adottare Indicare i tempi e i relativi effetti in termini di ricavi, di costi e di invesgtimenti delle iniziative da adottare. Le relative funzioni aziendali responsabili sono Indicare quali sono le relative funzioni aziendali responsabili. Non sono prospettabili iniziative alternative nel caso in cui le iniziative dovessero dimostrarsi inefficaci e si manifestassero scostamenti tra gli obiettivi pianificati e quelli raggiunti. Non sono mai stati predisposti piani aziendali. Il piano non è coerente con i piani redatti in precedenza e non vi sono differenze significative. Il piano non appare credibile. Non è fondato su intenzioni strategiche chiare e razionali, condivisibili da parte di un lettore informato quale è l’esperto, coerenti con la situazione di fatto dell’impresa e del contesto in cui opera. Le strategie di intervento e le iniziative industriali individuate dall’imprenditore non appaiono appropriate per il superamento delle cause della crisi.
A13: Le proiezioni dei flussi finanziari
